<?xml version="1.0" ?>
<robot name="gantry_robot" xmlns:xacro="http://www.ros.org/wiki/xacro">

<xacro:include filename="$(find gantry_bot)/description/materials.xacro" />
<xacro:include filename="$(find gantry_bot)/description/Base_link.trans" />
<xacro:include filename="$(find gantry_bot)/description/Base_link.gazebo" />

    <link name="base_link">
      <inertial>
        <origin xyz="-0.05 -1.407886535252211e-17 0.01778637770897833" rpy="0 0 0"/>
        <mass value="10.142199999999999"/>
        <inertia ixx="0.045365" iyy="0.09384" izz="0.119161" ixy="-0.0" iyz="0.0" ixz="-0.0"/>
      </inertial>
      <visual>
        <origin xyz="0 0 0" rpy="0 0 0"/>
        <geometry>
          <mesh filename="package://gantry_bot/meshes/base_link.stl" scale="0.001 0.001 0.001"/>
        </geometry>
        <material name="yellow"/>
      </visual>
      <collision>
        <origin xyz="0 0 0" rpy="0 0 0"/>
        <geometry>
          <mesh filename="package://gantry_bot/meshes/base_link.stl" scale="0.001 0.001 0.001"/>
        </geometry>
      </collision>
    </link>

    <link name="link_1_1">
      <inertial>
        <origin xyz="0.13000000000000006 0.00028345586432649173 0.0050000000000000044" rpy="0 0 0"/>
        <mass value="0.27188438956674926"/>
        <inertia ixx="1.3e-05" iyy="0.00296" izz="0.002961" ixy="-0.0" iyz="-0.0" ixz="-0.0"/>
      </inertial>
      <visual>
        <origin xyz="0.18 -0.0 -0.16" rpy="0 0 0"/>
        <geometry>
          <mesh filename="package://gantry_bot/meshes/link_1_1.stl" scale="0.001 0.001 0.001"/>
        </geometry>
        <material name="red"/>
      </visual>
      <collision>
        <origin xyz="0.18 -0.0 -0.16" rpy="0 0 0"/>
        <geometry>
          <mesh filename="package://gantry_bot/meshes/link_1_1.stl" scale="0.001 0.001 0.001"/>
        </geometry>
      </collision>
    </link>

    <link name="link_2_1">
      <inertial>
        <origin xyz="-0.012547699039425306 0.010238495269898402 -1.1102230246251565e-16" rpy="0 0 0"/>
        <mass value="0.1292558098779849"/>
        <inertia ixx="2.3e-05" iyy="1.2e-05" izz="2.5e-05" ixy="0.0" iyz="0.0" ixz="-0.0"/>
      </inertial>
      <visual>
        <origin xyz="0.05 -0.0005 -0.165" rpy="0 0 0"/>
        <geometry>
          <mesh filename="package://gantry_bot/meshes/link_2_1.stl" scale="0.001 0.001 0.001"/>
        </geometry>
        <material name="green"/>
      </visual>
      <collision>
        <origin xyz="0.05 -0.0005 -0.165" rpy="0 0 0"/>
        <geometry>
          <mesh filename="package://gantry_bot/meshes/link_2_1.stl" scale="0.001 0.001 0.001"/>
        </geometry>
      </collision>
    </link>

    <link name="link_3_1">
      <inertial>
        <origin xyz="1.9371516890576146e-10 4.917382889768618e-10 -0.001673387096774226" rpy="0 0 0"/>
        <mass value="0.06370888102092302"/>
        <inertia ixx="5.7e-05" iyy="5.7e-05" izz="1e-06" ixy="0.0" iyz="0.0" ixz="0.0"/>
      </inertial>
      <visual>
        <origin xyz="0.062 -0.0205 -0.175" rpy="0 0 0"/>
        <geometry>
        <mesh filename="package://gantry_bot/meshes/link_3_1.stl" scale="0.001 0.001 0.001"/>
        </geometry>
        <material name="blue"/>
      </visual>
      <collision>
        <origin xyz="0.062 -0.0205 -0.175" rpy="0 0 0"/>
        <geometry>
          <mesh filename="package://gantry_bot/meshes/link_3_1.stl" scale="0.001 0.001 0.001"/>
        </geometry>
      </collision>
    </link>

    <link name="end_effector_1">
      <inertial>
        <origin xyz="1.8784021560414033e-10 8.125000464098697e-10 -0.02431235615011955" rpy="0 0 0"/>
        <mass value="0.07548794288214095"/>
        <inertia ixx="1.1e-05" iyy="1.6e-05" izz="1.5e-05" ixy="0.0" iyz="0.0" ixz="0.0"/>
      </inertial>
      <visual>
        <origin xyz="0.062 -0.0205 -0.125" rpy="0 0 0"/>
        <geometry>
          <mesh filename="package://gantry_bot/meshes/end_effector_1.stl" scale="0.001 0.001 0.001"/>
        </geometry>
        <material name="purple"/>
      </visual>
      <collision>
        <origin xyz="0.062 -0.0205 -0.125" rpy="0 0 0"/>
        <geometry>
          <mesh filename="package://gantry_bot/meshes/end_effector_1.stl" scale="0.001 0.001 0.001"/>
        </geometry>
      </collision>
    </link>

    <joint name="Slider 1" type="prismatic">
      <origin xyz="-0.18 0.0 0.16" rpy="0 0 0"/>
      <parent link="base_link"/>
      <child link="link_1_1"/>
      <axis xyz="0.0 1.0 0.0"/>
      <limit upper="0.06" lower="-0.06" effort="100" velocity="100"/>
    </joint>

    <joint name="Slider 2" type="prismatic">
      <origin xyz="0.13 0.0005 0.005" rpy="0 0 0"/>
      <parent link="link_1_1"/>
      <child link="link_2_1"/>
      <axis xyz="1.0 -0.0 0.0"/>
      <limit upper="0.12" lower="-0.09" effort="100" velocity="100"/>
    </joint>

    <joint name="Slider 3" type="prismatic">
      <origin xyz="-0.012 0.02 0.01" rpy="0 0 0"/>
      <parent link="link_2_1"/>
      <child link="link_3_1"/>
      <axis xyz="-0.0 -0.0 -1.0"/>
      <limit upper="0.05" lower="-0.02" effort="100" velocity="100"/>
    </joint>

    <joint name="Ball 4" type="continuous">
      <origin xyz="0.0 0.0 -0.05" rpy="0 0 0"/>
      <parent link="link_3_1"/>
      <child link="end_effector_1"/>
    </joint>

</robot>
